{"uuid": "4ef55a5d-57ed-40ac-958a-060da4e288ff", "children": ["b768f10a-62ca-41f1-8863-e2722f92848f"], "befores": [{"name": "_Class__pytest_setup_class", "status": "broken", "statusDetails": {"message": "selenium.common.exceptions.WebDriverException: Message: An unknown server-side error occurred while processing the command. Original error: Could not find a connected Android device.\n\n", "trace": "  File \"d:\\xyrj\\python\\python\\lib\\site-packages\\pluggy\\callers.py\", line 187, in _multicall\n    res = hook_impl.function(*args)\n  File \"d:\\xyrj\\python\\python\\lib\\site-packages\\_pytest\\fixtures.py\", line 964, in pytest_fixture_setup\n    result = call_fixture_func(fixturefunc, request, kwargs)\n  File \"d:\\xyrj\\python\\python\\lib\\site-packages\\_pytest\\fixtures.py\", line 788, in call_fixture_func\n    res = next(it)\n  File \"d:\\xyrj\\python\\python\\lib\\site-packages\\_pytest\\python.py\", line 701, in xunit_setup_class_fixture\n    _call_with_optional_argument(func, self.obj)\n  File \"d:\\xyrj\\python\\python\\lib\\site-packages\\_pytest\\python.py\", line 632, in _call_with_optional_argument\n    func(arg)\n  File \"D:\\xyrj\\python\\HeiMaXiangMuTest\\autoToutiaoTest\\script\\app\\test_query_artical.py\", line 9, in setup_class\n    self.driver = DriverUtils.get_app_driver()\n  File \"D:\\xyrj\\python\\HeiMaXiangMuTest\\autoToutiaoTest\\utils.py\", line 142, in get_app_driver\n    cls.__app_driver = appium.webdriver.Remote(\"http://127.0.0.1:4723/wd/hub\", cap)\n  File \"d:\\xyrj\\python\\python\\lib\\site-packages\\appium\\webdriver\\webdriver.py\", line 155, in __init__\n    proxy\n  File \"d:\\xyrj\\python\\python\\lib\\site-packages\\selenium\\webdriver\\remote\\webdriver.py\", line 157, in __init__\n    self.start_session(capabilities, browser_profile)\n  File \"d:\\xyrj\\python\\python\\lib\\site-packages\\appium\\webdriver\\webdriver.py\", line 225, in start_session\n    response = self.execute(RemoteCommand.NEW_SESSION, parameters)\n  File \"d:\\xyrj\\python\\python\\lib\\site-packages\\selenium\\webdriver\\remote\\webdriver.py\", line 321, in execute\n    self.error_handler.check_response(response)\n  File \"d:\\xyrj\\python\\python\\lib\\site-packages\\selenium\\webdriver\\remote\\errorhandler.py\", line 242, in check_response\n    raise exception_class(message, screen, stacktrace)\n"}, "start": 1591927841672, "stop": 1591927876372}], "start": 1591927841672, "stop": 1591927876666}